Workbook
Name bank_spread: Вводы!$B$9
Name c_days_b: Вводы!$B$39
Name c_days_c: Вводы!$B$37
Name c_days_o: Вводы!$B$41
Name c_rate_b: Вводы!$B$38*(1+vat)*fx
Name c_rate_c: Вводы!$B$36*(1+vat)*fx
Name c_rate_o: Вводы!$B$40*(1+vat)*fx
Name fx: Вводы!$B$3
Name g_days_b: Вводы!$B$33
Name g_days_c: Вводы!$B$31
Name g_days_o: Вводы!$B$35
Name g_rate_b: Вводы!$B$32*(1+vat)*fx
Name g_rate_c: Вводы!$B$30*(1+vat)*fx
Name g_rate_o: Вводы!$B$34*(1+vat)*fx
Name ins: Вводы!$B$7
Name life: Вводы!$B$5
Name life_hopper: Вводы!$B$16
Name life_used: Вводы!$B$26
Name loan_share: Вводы!$B$10
Name loan_years: Вводы!$B$11
Name maint_covered: Вводы!$B$23*(1+vat)*fx
Name maint_gondola: Вводы!$B$24*(1+vat)*fx
Name maint_grain: Вводы!$B$22*(1+vat)*fx
Name maint_used_uplift: Вводы!$B$25
Name nbk: Вводы!$B$8
Name overhead_100: Вводы!$B$13
Name overhead_300: Вводы!$B$14
Name overhead_500: Вводы!$B$15
Name overhead_small: Вводы!$B$12
Name p_days_b: Вводы!$B$45
Name p_days_c: Вводы!$B$43
Name p_days_o: Вводы!$B$47
Name p_rate_b: Вводы!$B$44*(1+vat)*fx
Name p_rate_c: Вводы!$B$42*(1+vat)*fx
Name p_rate_o: Вводы!$B$46*(1+vat)*fx
Name price_covered: Вводы!$B$19*(1+vat)*fx
Name price_gondola: Вводы!$B$20*(1+vat)*fx
Name price_grain: Вводы!$B$18*(1+vat)*fx
Name q1_covered: Вводы!$B$51
Name q1_gondola: Вводы!$B$52
Name q1_grain: Вводы!$B$50
Name q2_covered: Вводы!$B$54
Name q2_gondola: Вводы!$B$55
Name q2_grain: Вводы!$B$53
Name residual: Вводы!$B$6
Name tax: Вводы!$B$4
Name used_coef: Вводы!$B$21
Name vat: Вводы!$B$58

Sheet Вводы
A1: Вводы модели — жёлтые ячейки можно менять
A2: Параметр | B2: Значение | C2: Единица | D2: Что это и откуда
A3: fx | B3: 5.24 | C3: тенге за 1 рубль | D3: Официальный курс НБК на 8 октября 2026: 5,24 тенге за рубль
A4: tax | B4: 0.2 | C4: доля | D4: Базовая ставка КПН с 2026 года, НК РК
A5: life | B5: 32 | C5: лет | D5: Срок службы крытого 11-1268 по КП и платформы 13-6953 по опубликованной характеристике. Хоппер 19-3255 — отдельная ячейка life_hopper, 30 лет
A6: residual | B6: 0.15 | C6: доля цены | D6: Допущение: остаточная стоимость в конце срока службы
A7: ins | B7: 0.0035 | C7: доля цены в год | D7: Допущение: страхование 0,35% стоимости в год
A8: nbk | B8: 0.1625 | C8: доля | D8: Базовая ставка НБК с 7 сентября 2026, коридор ±1 п.п.
A9: bank_spread | B9: 0.05 | C9: доля | D9: Допущение: надбавка банка к базовой ставке. Это не оферта
A10: loan_share | B10: 0.5 | C10: доля цены | D10: Доля долга в сравнении «покупка / кредит»
A11: loan_years | B11: 7 | C11: лет | D11: Срок кредита в модели
A12: overhead_small | B12: 0 | C12: тенге в год | D12: В расчёте не учтены. Затраты на офис в базу не входят: ячейка равна нулю. Впишите сумму в тенге, если нужно увидеть экономику с офисом.
A13: overhead_100 | B13: 0 | C13: тенге в год | D13: В расчёте не учтены. См. overhead_small.
A14: overhead_300 | B14: 0 | C14: тенге в год | D14: В расчёте не учтены. См. overhead_small.
... A16: life_hopper | B16: 30 | C16: лет | D16: КП ТОО «Railway Alliance» от 08.10.2026, модель 19-3255: назначенный срок службы 30 лет
A17: Цены и содержание одного вагона
A18: Хоппер 19-3255, цена нового, руб. FCA | B18: 4450000 | D18: КП ТОО «Railway Alliance» исх. № 183 от 08.10.2026 для ТОО «Integra Logistics»: 4 450 000 руб. FCA, самовывоз. НДС в КП не оговорён
A19: Крытый 11-1268, цена нового, руб. FCA | B19: 4950000 | D19: То же КП: 4 950 000 руб. FCA. Большекубовый крытый 174 м³, 4 люка на крыше
A20: Платформа 13-6953, цена нового, руб. FCA | B20: 4300000 | D20: То же КП: 4 300 000 руб. FCA. Фитинговая платформа под контейнеры и танк-контейнеры, рама 13,4 м
A21: Цена б/у к цене нового | B21: 0.5 | D21: Допущение: открытого индекса вторичного рынка на октябрь 2026 нет
A22: Содержание хоппера 19-3255, руб./год | B22: 175000 | D22: Сборка как у крытого хоппера: ДР около 130 тыс. без запчастей (2025) + допущение по запчастям, КР 400–500 тыс. раз в 12 лет. Отдельной калькуляции ремонта 19-3255 в открытом доступе нет
A23: Содержание крытого 11-1268, руб./год | B23: 185000 | D23: Та же логика, КР крытого 450–600 тыс.
A24: Содержание платформы 13-6953, руб./год | B24: 170000 | D24: Допущение, не суточная ставка ОЖдПС. ДР 130 тыс. без запчастей раз в 3 года, запчасти приняты равными работе, КР на уровне хоппера 400 тыс. раз в 12 лет, колёса — допущение. 879 ₽/сутки относятся к полувагону и сюда не переносятся
A25: Надбавка к ремонту б/у | B25: 0.2 | D25: Допущение: б/у дороже в содержании на 20%
A26: Остаточный срок б/у, лет | B26: 16 | D26: Допущение для вагона примерно середины срока службы
A28: Ставка и дни, когда ставка зарабатывается
A29: Жёлтая ставка — руб./сутки без НДС, как в источнике. В расчёте она становится тенге с НДС 16%. Дни — сколько суток в году вагон приносит ставку. Содержание платится за весь год. Порожний рейс платит грузоотправитель.
A30: Хоппер 19-3255, консервативная ставка | B30: 1200 | D30: Груз хоппера 19-3255 для расчёта — зерно: так задано заказчиком. В тексте КП груз модели не напечатан. Ставка 1 700 руб./сутки без НДС — базовый ориентир зернового ряда, ниже июльской аренды 1 910 и ниже августовского спота 2 300–3 500. С февраля длинные контракты не заключаются.
A31: Хоппер 19-3255, консервативные дни | B31: 180
A32: Хоппер 19-3255, базовая ставка — зерно | B32: 1700
A33: Хоппер 19-3255, базовые дни | B33: 230
A34: Хоппер 19-3255, оптимистичная ставка | B34: 2500
A35: Хоппер 19-3255, оптимистичные дни | B35: 280
A36: Крытый, консервативная ставка | B36: 1100 | D36: Последняя открытая абсолютная ставка крытого — Argus, октябрь 2024: 138 м³ 2 620–2 710 ₽, 158 м³ 2 750–2 890 ₽. ИЦО в 2025–2026 публикует только направление: ставка снижается. 1 500 ₽ для большекубового 11-1268 (174 м³) — допущение ниже печати 2024 года, не котировка.
A37: Крытый, консервативные дни | B37: 170
A38: Крытый, базовая ставка — ДОПУЩЕНИЕ | B38: 1500
A39: Крытый, базовые дни | B39: 220
A40: Крытый, оптимистичная ставка | B40: 2000
A41: Крытый, оптимистичные дни | B41: 270
A42: Платформа 13-6953, консервативная ставка | B42: 700 | D42: 13-6953 — фитинговая платформа с рамой 13,4 м, класс 40 футов. База 1 100 ₽ — индикатив ЦЦИ на 40-футовую платформу в июле 2026, без НДС. Консерватив 700 ₽ — верх спота августа 2025 (ИЦО: 500–700). Оптимум 1 500 ₽ — верх длинного контракта лета 2026, не дальневосточный спот 2 000–2 500.
...

Sheet Юнит
A1: Экономика одного нового вагона
I2: Денежные потоки для IRR (год 0 — покупка, последний год + остаток)
A3: Показатель | B3: 19-3255 конс. | C3: 19-3255 база | D3: 19-3255 опт. | E3: 11-1268 конс. | F3: 11-1268 база | G3: 11-1268 опт. | I3: =B3 -> 0 | J3: =C3 -> 0 | K3: =D3 -> 0 | L3: =E3 -> 0 | M3: =F3 -> 0 | N3: =G3 -> 0
A4: Цена, тенге с НДС | B4: =price_grain -> 0 | C4: =price_grain -> 0 | D4: =price_grain -> 0 | E4: =price_covered -> 0 | F4: =price_covered -> 0 | G4: =price_covered -> 0 | I4: =-B4 -> 0 | J4: =-C4 -> 0 | K4: =-D4 -> 0 | L4: =-E4 -> 0 | M4: =-F4 -> 0 | N4: =-G4 -> 0
A5: Ставка, тенге/сутки с НДС | B5: =g_rate_c -> 0 | C5: =g_rate_b -> 0 | D5: =g_rate_o -> 0 | E5: =c_rate_c -> 0 | F5: =c_rate_b -> 0 | G5: =c_rate_o -> 0 | I5: =B16 -> 0 | J5: =C16 -> 0 | K5: =D16 -> 0 | L5: =E16 -> 0 | M5: =F16 -> 0 | N5: =G16 -> 0
A6: Дни со ставкой | B6: =g_days_c -> 0 | C6: =g_days_b -> 0 | D6: =g_days_o -> 0 | E6: =c_days_c -> 0 | F6: =c_days_b -> 0 | G6: =c_days_o -> 0 | I6: =B16 -> 0 | J6: =C16 -> 0 | K6: =D16 -> 0 | L6: =E16 -> 0 | M6: =F16 -> 0 | N6: =G16 -> 0
A7: Выручка, тенге/год | B7: =B5*B6 -> 0 | C7: =C5*C6 -> 0 | D7: =D5*D6 -> 0 | E7: =E5*E6 -> 0 | F7: =F5*F6 -> 0 | G7: =G5*G6 -> 0 | I7: =B16 -> 0 | J7: =C16 -> 0 | K7: =D16 -> 0 | L7: =E16 -> 0 | M7: =F16 -> 0 | N7: =G16 -> 0
A8: Содержание, тенге/год | B8: =maint_grain -> 0 | C8: =maint_grain -> 0 | D8: =maint_grain -> 0 | E8: =maint_covered -> 0 | F8: =maint_covered -> 0 | G8: =maint_covered -> 0 | I8: =B16 -> 0 | J8: =C16 -> 0 | K8: =D16 -> 0 | L8: =E16 -> 0 | M8: =F16 -> 0 | N8: =G16 -> 0
A9: Страхование, тенге/год | B9: =B4*ins -> 0 | C9: =C4*ins -> 0 | D9: =D4*ins -> 0 | E9: =E4*ins -> 0 | F9: =F4*ins -> 0 | G9: =G4*ins -> 0 | I9: =B16 -> 0 | J9: =C16 -> 0 | K9: =D16 -> 0 | L9: =E16 -> 0 | M9: =F16 -> 0 | N9: =G16 -> 0
A10: OPEX, тенге/год | B10: =B8+B9 -> 0 | C10: =C8+C9 -> 0 | D10: =D8+D9 -> 0 | E10: =E8+E9 -> 0 | F10: =F8+F9 -> 0 | G10: =G8+G9 -> 0 | I10: =B16 -> 0 | J10: =C16 -> 0 | K10: =D16 -> 0 | L10: =E16 -> 0 | M10: =F16 -> 0 | N10: =G16 -> 0
A11: EBITDA, тенге/год | B11: =B7-B10 -> 0 | C11: =C7-C10 -> 0 | D11: =D7-D10 -> 0 | E11: =E7-E10 -> 0 | F11: =F7-F10 -> 0 | G11: =G7-G10 -> 0 | I11: =B16 -> 0 | J11: =C16 -> 0 | K11: =D16 -> 0 | L11: =E16 -> 0 | M11: =F16 -> 0 | N11: =G16 -> 0
A12: Амортизация, тенге/год | B12: =B4*(1-residual)/life_hopper -> 0 | C12: =C4*(1-residual)/life_hopper -> 0 | D12: =D4*(1-residual)/life_hopper -> 0 | E12: =E4*(1-residual)/life -> 0 | F12: =F4*(1-residual)/life -> 0 | G12: =G4*(1-residual)/life -> 0 | I12: =B16 -> 0 | J12: =C16 -> 0 | K12: =D16 -> 0 | L12: =E16 -> 0 | M12: =F16 -> 0 | N12: =G16 -> 0
A13: Прибыль до налога | B13: =B11-B12 -> 0 | C13: =C11-C12 -> 0 | D13: =D11-D12 -> 0 | E13: =E11-E12 -> 0 | F13: =F11-F12 -> 0 | G13: =G11-G12 -> 0 | I13: =B16 -> 0 | J13: =C16 -> 0 | K13: =D16 -> 0 | L13: =E16 -> 0 | M13: =F16 -> 0 | N13: =G16 -> 0
A14: КПН | B14: =MAX(B13,0)*tax -> 0 | C14: =MAX(C13,0)*tax -> 0 | D14: =MAX(D13,0)*tax -> 0 | E14: =MAX(E13,0)*tax -> 0 | F14: =MAX(F13,0)*tax -> 0 | G14: =MAX(G13,0)*tax -> 0 | I14: =B16 -> 0 | J14: =C16 -> 0 | K14: =D16 -> 0 | L14: =E16 -> 0 | M14: =F16 -> 0 | N14: =G16 -> 0
A15: Чистая прибыль | B15: =B13-B14 -> 0 | C15: =C13-C14 -> 0 | D15: =D13-D14 -> 0 | E15: =E13-E14 -> 0 | F15: =F13-F14 -> 0 | G15: =G13-G14 -> 0 | I15: =B16 -> 0 | J15: =C16 -> 0 | K15: =D16 -> 0 | L15: =E16 -> 0 | M15: =F16 -> 0 | N15: =G16 -> 0
A16: Денежный поток после налога | B16: =B11-B14 -> 0 | C16: =C11-C14 -> 0 | D16: =D11-D14 -> 0 | E16: =E11-E14 -> 0 | F16: =F11-F14 -> 0 | G16: =G11-G14 -> 0 | I16: =B16 -> 0 | J16: =C16 -> 0 | K16: =D16 -> 0 | L16: =E16 -> 0 | M16: =F16 -> 0 | N16: =G16 -> 0
A17: Окупаемость по EBITDA, лет | B17: =IF(B11<=0,"не окупается",B4/B11) -> 0 | C17: =IF(C11<=0,"не окупается",C4/C11) -> 0 | D17: =IF(D11<=0,"не окупается",D4/D11) -> 0 | E17: =IF(E11<=0,"не окупается",E4/E11) -> 0 | F17: =IF(F11<=0,"не окупается",F4/F11) -> 0 | G17: =IF(G11<=0,"не окупается",G4/G11) -> 0 | I17: =B16 -> 0 | J17: =C16 -> 0 | K17: =D16 -> 0 | L17: =E16 -> 0 | M17: =F16 -> 0 | N17: =G16 -> 0
A18: Окупаемость по ден. потоку, лет | B18: =IF(B16<=0,"не окупается",B4/B16) -> 0 | C18: =IF(C16<=0,"не окупается",C4/C16) -> 0 | D18: =IF(D16<=0,"не окупается",D4/D16) -> 0 | E18: =IF(E16<=0,"не окупается",E4/E16) -> 0 | F18: =IF(F16<=0,"не окупается",F4/F16) -> 0 | G18: =IF(G16<=0,"не окупается",G4/G16) -> 0 | I18: =B16 -> 0 | J18: =C16 -> 0 | K18: =D16 -> 0 | L18: =E16 -> 0 | M18: =F16 -> 0 | N18: =G16 -> 0
A19: EBITDA-маржа | B19: =IF(B7=0,NA(),B11/B7) -> 0 | C19: =IF(C7=0,NA(),C11/C7) -> 0 | D19: =IF(D7=0,NA(),D11/D7) -> 0 | E19: =IF(E7=0,NA(),E11/E7) -> 0 | F19: =IF(F7=0,NA(),F11/F7) -> 0 | G19: =IF(G7=0,NA(),G11/G7) -> 0 | I19: =B16 -> 0 | J19: =C16 -> 0 | K19: =D16 -> 0 | L19: =E16 -> 0 | M19: =F16 -> 0 | N19: =G16 -> 0
A20: IRR на срок службы | B20: =IRR(I4:I36) -> 0 | C20: =IRR(J4:J36) -> 0 | D20: =IRR(K4:K36) -> 0 | E20: =IRR(L4:L36) -> 0 | F20: =IRR(M4:M36) -> 0 | G20: =IRR(N4:N36) -> 0 | I20: =B16 -> 0 | J20: =C16 -> 0 | K20: =D16 -> 0 | L20: =E16 -> 0 | M20: =F16 -> 0 | N20: =G16 -> 0
A21: ROI, денежный поток / цена | B21: =IF(B4=0,NA(),B16/B4) -> 0 | C21: =IF(C4=0,NA(),C16/C4) -> 0 | D21: =IF(D4=0,NA(),D16/D4) -> 0 | E21: =IF(E4=0,NA(),E16/E4) -> 0 | F21: =IF(F4=0,NA(),F16/F4) -> 0 | G21: =IF(G4=0,NA(),G16/G4) -> 0 | I21: =B16 -> 0 | J21: =C16 -> 0 | K21: =D16 -> 0 | L21: =E16 -> 0 | M21: =F16 -> 0 | N21: =G16 -> 0
A22: Платформа 13-6953 | B22: =NPV(nbk,I5:I36)+I4 -> 0 | C22: =NPV(nbk,J5:J36)+J4 -> 0 | D22: =NPV(nbk,K5:K36)+K4 -> 0 | E22: =NPV(nbk,L5:L36)+L4 -> 0 | F22: =NPV(nbk,M5:M36)+M4 -> 0 | G22: =NPV(nbk,N5:N36)+N4 -> 0 | I22: =B16 -> 0 | J22: =C16 -> 0 | K22: =D16 -> 0 | L22: =E16 -> 0 | M22: =F16 -> 0 | N22: =G16 -> 0
A23: Показатель | B23: Консервативный | C23: Базовый | D23: Оптимистичный | I23: =B16 -> 0 | J23: =C16 -> 0 | K23: =D16 -> 0 | L23: =E16 -> 0 | M23: =F16 -> 0 | N23: =G16 -> 0
A24: Цена, тенге с НДС | B24: =price_gondola -> 0 | C24: =price_gondola -> 0 | D24: =price_gondola -> 0 | I24: =B16 -> 0 | J24: =C16 -> 0 | K24: =D16 -> 0 | L24: =E16 -> 0 | M24: =F16 -> 0 | N24: =G16 -> 0
A25: Ставка, тенге/сутки с НДС | B25: =p_rate_c -> 0 | C25: =p_rate_b -> 0 | D25: =p_rate_o -> 0 | I25: =B16 -> 0 | J25: =C16 -> 0 | K25: =D16 -> 0 | L25: =E16 -> 0 | M25: =F16 -> 0 | N25: =G16 -> 0
A26: Дни со ставкой | B26: =p_days_c -> 0 | C26: =p_days_b -> 0 | D26: =p_days_o -> 0 | I26: =B16 -> 0 | J26: =C16 -> 0 | K26: =D16 -> 0 | L26: =E16 -> 0 | M26: =F16 -> 0 | N26: =G16 -> 0
A27: Выручка | B27: =B25*B26 -> 0 | C27: =C25*C26 -> 0 | D27: =D25*D26 -> 0 | I27: =B16 -> 0 | J27: =C16 -> 0 | K27: =D16 -> 0 | L27: =E16 -> 0 | M27: =F16 -> 0 | N27: =G16 -> 0
A28: Содержание | B28: =maint_gondola -> 0 | C28: =maint_gondola -> 0 | D28: =maint_gondola -> 0 | I28: =B16 -> 0 | J28: =C16 -> 0 | K28: =D16 -> 0 | L28: =E16 -> 0 | M28: =F16 -> 0 | N28: =G16 -> 0
A29: Страхование | B29: =B24*ins -> 0 | C29: =C24*ins -> 0 | D29: =D24*ins -> 0 | I29: =B16 -> 0 | J29: =C16 -> 0 | K29: =D16 -> 0 | L29: =E16 -> 0 | M29: =F16 -> 0 | N29: =G16 -> 0
A30: OPEX | B30: =B28+B29 -> 0 | C30: =C28+C29 -> 0 | D30: =D28+D29 -> 0 | I30: =B16 -> 0 | J30: =C16 -> 0 | K30: =D16 -> 0 | L30: =E16 -> 0 | M30: =F16 -> 0 | N30: =G16 -> 0
A31: EBITDA | B31: =B27-B30 -> 0 | C31: =C27-C30 -> 0 | D31: =D27-D30 -> 0 | I31: =B16 -> 0 | J31: =C16 -> 0 | K31: =D16 -> 0 | L31: =E16 -> 0 | M31: =F16 -> 0 | N31: =G16 -> 0
A32: Амортизация | B32: =B24*(1-residual)/life -> 0 | C32: =C24*(1-residual)/life -> 0 | D32: =D24*(1-residual)/life -> 0 | I32: =B16 -> 0 | J32: =C16 -> 0 | K32: =D16 -> 0 | L32: =E16 -> 0 | M32: =F16 -> 0 | N32: =G16 -> 0
A33: Прибыль до налога | B33: =B31-B32 -> 0 | C33: =C31-C32 -> 0 | D33: =D31-D32 -> 0 | I33: =B16 -> 0 | J33: =C16 -> 0 | K33: =D16 -> 0 | L33: =E16 -> 0 | M33: =F16 -> 0 | N33: =G16 -> 0
A34: КПН | B34: =MAX(B33,0)*tax -> 0 | C34: =MAX(C33,0)*tax -> 0 | D34: =MAX(D33,0)*tax -> 0 | I34: =B16+B4*residual -> 0 | J34: =C16+C4*residual -> 0 | K34: =D16+D4*residual -> 0 | L34: =E16 -> 0 | M34: =F16 -> 0 | N34: =G16 -> 0
A35: Чистая прибыль | B35: =B33-B34 -> 0 | C35: =C33-C34 -> 0 | D35: =D33-D34 -> 0 | I35: ="" -> 0 | J35: ="" -> 0 | K35: ="" -> 0 | L35: =E16 -> 0 | M35: =F16 -> 0 | N35: =G16 -> 0
A36: Денежный поток после налога | B36: =B31-B34 -> 0 | C36: =C31-C34 -> 0 | D36: =D31-D34 -> 0 | I36: ="" -> 0 | J36: ="" -> 0 | K36: ="" -> 0 | L36: =E16+E4*residual -> 0 | M36: =F16+F4*residual -> 0 | N36: =G16+G4*residual -> 0
A37: Окупаемость по EBITDA, лет | B37: =IF(B31<=0,"не окупается",B24/B31) -> 0 | C37: =IF(C31<=0,"не окупается",C24/C31) -> 0 | D37: =IF(D31<=0,"не окупается",D24/D31) -> 0
A38: IRR на срок службы | B38: =IRR(I41:I73) -> 0 | C38: =IRR(J41:J73) -> 0 | D38: =IRR(K41:K73) -> 0
A39: ROI, денежный поток / цена | B39: =IF(B24=0,NA(),B36/B24) -> 0 | C39: =IF(C24=0,NA(),C36/C24) -> 0 | D39: =IF(D24=0,NA(),D36/D24) -> 0
A40: NPV при ставке НБК, тенге | B40: =NPV(nbk,I42:I73)+I41 -> 0 | C40: =NPV(nbk,J42:J73)+J41 -> 0 | D40: =NPV(nbk,K42:K73)+K41 -> 0
...

Sheet Портфель
A1: Заказ из КП и тот же заказ, удвоенный. Базовый сценарий
A2: EBITDA одного вагона берётся из листа «Юнит»: хоппер 19-3255 — C11, крытый 11-1268 — F11, платформа 13-6953 — C31. Груз хоппера — зерно. Офис в базе равен нулю.
A4: Показатель | B4: 10 + 10 + 10 | C4: 20 + 20 + 20
A5: Зерновозы, шт. | B5: =q1_grain -> 0 | C5: =q2_grain -> 0
A6: Крытые, шт. | B6: =q1_covered -> 0 | C6: =q2_covered -> 0
A7: Полувагоны, шт. | B7: =q1_gondola -> 0 | C7: =q2_gondola -> 0
A8: CAPEX, тенге с НДС | B8: =B5*price_grain+B6*price_covered+B7*price_gondola -> 0 | C8: =C5*price_grain+C6*price_covered+C7*price_gondola -> 0
A9: CAPEX, млн тенге | B9: =B8/1000000 -> 0 | C9: =C8/1000000 -> 0
A10: Выручка, тенге/год | B10: =B5*'Юнит'!C7+B6*'Юнит'!F7+B7*'Юнит'!C27 -> 0 | C10: =C5*'Юнит'!C7+C6*'Юнит'!F7+C7*'Юнит'!C27 -> 0
A11: EBITDA вагонов, тенге/год | B11: =B5*'Юнит'!C11+B6*'Юнит'!F11+B7*'Юнит'!C31 -> 0 | C11: =C5*'Юнит'!C11+C6*'Юнит'!F11+C7*'Юнит'!C31 -> 0
A12: Офис, тенге/год — в базе ноль | B12: =overhead_small -> 0 | C12: =overhead_small -> 0
A13: EBITDA после офиса | B13: =B11-B12 -> 0 | C13: =C11-C12 -> 0
A14: Окупаемость вагонов без офиса, лет | B14: =IF(B11<=0,"не окупается",B8/B11) -> 0 | C14: =IF(C11<=0,"не окупается",C8/C11) -> 0
A15: Окупаемость с офисом, лет | B15: =IF(B13<=0,"не окупается",B8/B13) -> 0 | C15: =IF(C13<=0,"не окупается",C8/C13) -> 0
A16: Затраты на офис в этих цифрах не учтены: overhead_small = 0. Любой реальный офис уменьшит EBITDA и удлинит окупаемость. Порожний рейс платит грузоотправитель. Доставка и приёмка сверх FCA в цену не входят.
A18: Тот же парк в оптимистичном сценарии
A20: Показатель | B20: 10 + 10 + 10 | C20: 20 + 20 + 20
A21: EBITDA вагонов, тенге/год | B21: =B5*'Юнит'!D11+B6*'Юнит'!G11+B7*'Юнит'!D31 -> 0 | C21: =C5*'Юнит'!D11+C6*'Юнит'!G11+C7*'Юнит'!D31 -> 0
A22: EBITDA после офиса | B22: =B21-B12 -> 0 | C22: =C21-C12 -> 0
A23: Окупаемость с офисом, лет | B23: =IF(B22<=0,"не окупается",B8/B22) -> 0 | C23: =IF(C22<=0,"не окупается",C8/C22) -> 0

Sheet Барьер
A1: Какая ставка нужна, чтобы вагон окупился
A2: Считается при базовом числе дней. Ставка безубыточности покрывает содержание и страхование, но не возвращает цену вагона.
A4: Порог | B4: Хоппер 19-3255 | C4: Крытый 11-1268 | D4: Платформа 13-6953
A5: Дни базового сценария | B5: ='Юнит'!C6 -> 0 | C5: ='Юнит'!F6 -> 0 | D5: ='Юнит'!C26 -> 0
A6: OPEX, тенге/год | B6: ='Юнит'!C10 -> 0 | C6: ='Юнит'!F10 -> 0 | D6: ='Юнит'!C30 -> 0
A7: Ставка денежной безубыточности, тенге/сутки | B7: =B6/B5 -> 0 | C7: =C6/C5 -> 0 | D7: =D6/D5 -> 0
A8: Ставка для окупаемости 8 лет | B8: =('Юнит'!C4/8+B6)/B5 -> 0 | C8: =('Юнит'!F4/8+C6)/C5 -> 0 | D8: =('Юнит'!C24/8+D6)/D5 -> 0
A9: Ставка для окупаемости 10 лет | B9: =('Юнит'!C4/10+B6)/B5 -> 0 | C9: =('Юнит'!F4/10+C6)/C5 -> 0 | D9: =('Юнит'!C24/10+D6)/D5 -> 0
A10: Ставка для окупаемости 12 лет | B10: =('Юнит'!C4/12+B6)/B5 -> 0 | C10: =('Юнит'!F4/12+C6)/C5 -> 0 | D10: =('Юнит'!C24/12+D6)/D5 -> 0
A11: Ставка для окупаемости 15 лет | B11: =('Юнит'!C4/15+B6)/B5 -> 0 | C11: =('Юнит'!F4/15+C6)/C5 -> 0 | D11: =('Юнит'!C24/15+D6)/D5 -> 0
A12: Рыночный ориентир, тенге/сутки с НДС | B12: 11 610, аренда июля 2025 | C12: печать 2024: 16,7–17,6 тыс. | D12: 6686
A13: Рыночный ориентир зерновоза — аренда июля 2025, 1 910 руб./сутки («Паровоз Лизинг»), не августовский спот. Полувагон — долгосрочная аренда августа 2025, 900 руб./сутки (ИЦО). Крытый ориентир в открытом источнике отсутствует.
A15: Б/у хоппер 19-3255: цена = цена нового × used_coef, содержание × (1+maint_used_uplift), срок = life_used. Это не цена из КП: КП даёт только новый вагон. Коэффициент 50% — допущение.
A17: Б/у хоппер 19-3255 | B17: База | C17: Оптимистичный
A18: Цена, тенге с НДС | B18: =price_grain*used_coef -> 0 | C18: =B18 -> 0
A19: Содержание, тенге/год | B19: =maint_grain*(1+maint_used_uplift) -> 0 | C19: =B19 -> 0
A20: OPEX | B20: =B19+B18*ins -> 0 | C20: =C19+C18*ins -> 0
A21: Выручка | B21: =g_rate_b*g_days_b -> 0 | C21: =g_rate_o*g_days_o -> 0
A22: EBITDA | B22: =B21-B20 -> 0 | C22: =C21-C20 -> 0
A23: Окупаемость по EBITDA, лет | B23: =IF(B22<=0,"не окупается",B18/B22) -> 0 | C23: =IF(C22<=0,"не окупается",C18/C22) -> 0
A24: Амортизация, тенге/год | B24: =B18*(1-residual)/life_used -> 0 | C24: =C18*(1-residual)/life_used -> 0
A25: Прибыль до налога | B25: =B22-B24 -> 0 | C25: =C22-C24 -> 0
A26: КПН | B26: =MAX(B25,0)*tax -> 0 | C26: =MAX(C25,0)*tax -> 0
A27: Денежный поток после налога | B27: =B22-B26 -> 0 | C27: =C22-C26 -> 0
A28: ROI, денежный поток / цена | B28: =IF(B18=0,NA(),B27/B18) -> 0 | C28: =IF(C18=0,NA(),C27/C18) -> 0
A29: IRR на остаточный срок | B29: =IRR(H40:H72) -> 0 | C29: =IRR(I40:I72) -> 0
A30: NPV при ставке НБК, тенге | B30: =NPV(nbk,H41:H72)+H40 -> 0 | C30: =NPV(nbk,I41:I72)+I40 -> 0
A32: Потоки б/у для IRR: год 0 в строке 40, дальше пустая ячейка после life_used.
H39: Б/у база | I39: Б/у оптимум
H40: =-B18 -> 0 | I40: =-C18 -> 0
H41: =IF(1>life_used,"",IF(1=life_used,B27+B18*residual,B27)) -> 0 | I41: =IF(1>life_used,"",IF(1=life_used,C27+C18*residual,C27)) -> 0
H42: =IF(2>life_used,"",IF(2=life_used,B27+B18*residual,B27)) -> 0 | I42: =IF(2>life_used,"",IF(2=life_used,C27+C18*residual,C27)) -> 0
H43: =IF(3>life_used,"",IF(3=life_used,B27+B18*residual,B27)) -> 0 | I43: =IF(3>life_used,"",IF(3=life_used,C27+C18*residual,C27)) -> 0
H44: =IF(4>life_used,"",IF(4=life_used,B27+B18*residual,B27)) -> 0 | I44: =IF(4>life_used,"",IF(4=life_used,C27+C18*residual,C27)) -> 0
H45: =IF(5>life_used,"",IF(5=life_used,B27+B18*residual,B27)) -> 0 | I45: =IF(5>life_used,"",IF(5=life_used,C27+C18*residual,C27)) -> 0
H46: =IF(6>life_used,"",IF(6=life_used,B27+B18*residual,B27)) -> 0 | I46: =IF(6>life_used,"",IF(6=life_used,C27+C18*residual,C27)) -> 0
H47: =IF(7>life_used,"",IF(7=life_used,B27+B18*residual,B27)) -> 0 | I47: =IF(7>life_used,"",IF(7=life_used,C27+C18*residual,C27)) -> 0
H48: =IF(8>life_used,"",IF(8=life_used,B27+B18*residual,B27)) -> 0 | I48: =IF(8>life_used,"",IF(8=life_used,C27+C18*residual,C27)) -> 0
H49: =IF(9>life_used,"",IF(9=life_used,B27+B18*residual,B27)) -> 0 | I49: =IF(9>life_used,"",IF(9=life_used,C27+C18*residual,C27)) -> 0
H50: =IF(10>life_used,"",IF(10=life_used,B27+B18*residual,B27)) -> 0 | I50: =IF(10>life_used,"",IF(10=life_used,C27+C18*residual,C27)) -> 0
...

Sheet Масштаб
A1: Парк 20 / 50 / 100 / 300 / 500 в базовом сценарии
A2: Смешанный парк повторяет заказ: по трети хопперов 19-3255, крытых 11-1268 и платформ 13-6953. Рядом — парк только из зерновых хопперов. Офис в базе равен нулю.
B4: 20 | C4: 50 | D4: 100 | E4: 300 | F4: 500
A5: Постоянные расходы, тенге | B5: =overhead_small -> 0 | C5: =overhead_small -> 0 | D5: =overhead_100 -> 0 | E5: =overhead_300 -> 0 | F5: =overhead_500 -> 0
A6: Офис в расчёте, тенге (сейчас 0) | B6: =B5 -> 0 | C6: =C5 -> 0 | D6: =D5 -> 0 | E6: =E5 -> 0 | F6: =F5 -> 0
A8: Смешанный парк: CAPEX, тенге с НДС | B8: =20*((price_grain+price_covered+price_gondola)/3) -> 0 | C8: =50*((price_grain+price_covered+price_gondola)/3) -> 0 | D8: =100*((price_grain+price_covered+price_gondola)/3) -> 0 | E8: =300*((price_grain+price_covered+price_gondola)/3) -> 0 | F8: =500*((price_grain+price_covered+price_gondola)/3) -> 0
A9: Смешанный парк: EBITDA вагонов | B9: =20*(('Юнит'!C11+'Юнит'!F11+'Юнит'!C31)/3) -> 0 | C9: =50*(('Юнит'!C11+'Юнит'!F11+'Юнит'!C31)/3) -> 0 | D9: =100*(('Юнит'!C11+'Юнит'!F11+'Юнит'!C31)/3) -> 0 | E9: =300*(('Юнит'!C11+'Юнит'!F11+'Юнит'!C31)/3) -> 0 | F9: =500*(('Юнит'!C11+'Юнит'!F11+'Юнит'!C31)/3) -> 0
A10: Смешанный парк: EBITDA после офиса | B10: =B9-B6 -> 0 | C10: =C9-C6 -> 0 | D10: =D9-D6 -> 0 | E10: =E9-E6 -> 0 | F10: =F9-F6 -> 0
A11: Окупаемость с офисом, лет | B11: =IF(B10<=0,"не окупается",B8/B10) -> 0 | C11: =IF(C10<=0,"не окупается",C8/C10) -> 0 | D11: =IF(D10<=0,"не окупается",D8/D10) -> 0 | E11: =IF(E10<=0,"не окупается",E8/E10) -> 0 | F11: =IF(F10<=0,"не окупается",F8/F10) -> 0
A13: Только хопперы 19-3255: CAPEX, тенге с НДС | B13: =20*price_grain -> 0 | C13: =50*price_grain -> 0 | D13: =100*price_grain -> 0 | E13: =300*price_grain -> 0 | F13: =500*price_grain -> 0
A14: Только хопперы: EBITDA вагонов | B14: =20*'Юнит'!C11 -> 0 | C14: =50*'Юнит'!C11 -> 0 | D14: =100*'Юнит'!C11 -> 0 | E14: =300*'Юнит'!C11 -> 0 | F14: =500*'Юнит'!C11 -> 0
A15: Только хопперы: EBITDA после офиса | B15: =B14-B6 -> 0 | C15: =C14-C6 -> 0 | D15: =D14-D6 -> 0 | E15: =E14-E6 -> 0 | F15: =F14-F6 -> 0
A16: Окупаемость с офисом, лет | B16: =IF(B15<=0,"не окупается",B13/B15) -> 0 | C16: =IF(C15<=0,"не окупается",C13/C15) -> 0 | D16: =IF(D15<=0,"не окупается",D13/D15) -> 0 | E16: =IF(E15<=0,"не окупается",E13/E15) -> 0 | F16: =IF(F15<=0,"не окупается",F13/F15) -> 0
A17: Масштаб не лечит слабую единицу. Если один вагон не покрывает стоимость денег, пятьсот вагонов увеличивают и выручку, и замороженный капитал.

Sheet Финансирование
A1: Покупка, кредит, лизинг — один новый зерновой хоппер 19-3255, базовый сценарий, тенге с НДС
B3: Свои деньги | C3: Кредит 50% | D3: Фин. лизинг | E3: Операционная аренда
A4: Цена / объём финансирования, тенге с НДС | B4: =price_grain -> 0 | C4: =price_grain*loan_share -> 0 | D4: =price_grain*0.8 -> 0 | E4: 0, вагон не покупается
A5: Собственный капитал на старте, тенге | B5: =price_grain -> 0 | C5: =price_grain*(1-loan_share) -> 0 | D5: =price_grain*0.2 -> 0 | E5: Депозит 2 месяца ставки
A6: Ставка долга | B6: — | C6: =nbk+bank_spread -> 0 | D6: 0.22 | E6: рыночная аренда
A7: Платёж в год, тенге | B7: 0 | C7: =PMT(C6,loan_years,-C4) -> 0 | D7: =PMT(D6,loan_years,-D4) -> 0 | E7: =g_rate_b*365 -> 0
A8: EBITDA базового зерновоза | B8: ='Юнит'!C11 -> 0 | C8: ='Юнит'!C11 -> 0 | D8: ='Юнит'!C11 -> 0 | E8: Спреда нет, если сдаёте по той же ставке
A9: EBITDA − долговой платёж | B9: =B8-B7 -> 0 | C9: =C8-C7 -> 0 | D9: =D8-D7 -> 0
A10: DSCR (EBITDA / платёж) | B10: — | C10: =IF(C7=0,"—",C8/C7) -> 0 | D10: =IF(D7=0,"—",D8/D7) -> 0
A11: Денежная доходность на собственный капитал | B11: =IF(B5=0,NA(),B9/B5) -> 0 | C11: =IF(C5=0,NA(),C9/C5) -> 0 | D11: =IF(D5=0,NA(),D9/D5) -> 0
A12: Платёж в месяц, тенге | B12: 0 | C12: =PMT(C6/12,loan_years*12,-C4) -> 0 | D12: =PMT(D6/12,loan_years*12,-D4) -> 0
A13: Операционная аренда в столбце E — это отказ от покупки: вы платите рыночную ставку и не несёте остаточный риск. При текущем рынке спред пересдачи близок к нулю. Финансовый лизинг в модели: аванс 20%, ставка 22% годовых, срок 7 лет — допущение, не коммерческое предложение лизинговой компании. Кредит: базовый 16,25% + надбавка 5 п.п. Месячный платёж — аннуитет. Доходность на капитал здесь денежная: (EBITDA − долговой платёж) / собственные деньги на старте. Это не бухгалтерский ROE.

Sheet Источники
A1: Источники, на которые опираются жёлтые вводы
A3: Блок | B3: Источник
A4: Курс | B4: Национальный Банк Казахстана, официальный курс на 8 октября 2026: 1 RUB = 5,24 KZT.
A5: Коммерческое предложение | B5: ТОО «Railway Alliance», исх. № 183 от 08.10.2026, директору ТОО «Integra Logistics». FCA, самовывоз: хоппер 19-3255 — 4 450 000 руб., крытый 11-1268 — 4 950 000 руб., платформа 13-6953 — 4 300 000 руб. Аванс 70%, остаток 30% после акта. Срок КП — 10 дней. НДС в цене не оговорён. В том же КП, но не в расчёте: зерновой хоппер 19-3058 за 4 400 000 и хоппер 19-1274-01 за 4 300 000.
A6: Базовая ставка | B6: НБК, решение от 4 сентября 2026: 16,25% с 7 сентября 2026, коридор ±1 п.п. Следующее плановое решение — 23 октября 2026.
A7: Налоги | B7: НК РК с 1 января 2026: базовая ставка КПН 20% (КГД), НДС 16%. Налог на имущество считается от зданий и сооружений; на грузовой вагон в модели не начисляется.
A8: Перевозки, всего | B8: БНС РК, «Транспорт в Республике Казахстан», январь–декабрь 2025: 1 163,6 млн т, +7,9%; грузооборот 584,3 млрд т-км, +13,6%.
A9: Железная дорога, БНС | B9: Там же: 466,7 млн т, +6,8%; грузооборот 361,3 млрд т-км, +10,2%.
A10: Автомобильный | B10: Там же и пересказ TELS/ati.su: 352,7 млн т, +2,8%; 1,4 трлн тенге; грузооборот +32,8%.
A11: Сеть КТЖ | B11: КТЖ для Kazinform: 2025 год — 319,97 млн т, в том числе внутри республики 176,91, экспорт 89,23, импорт 20,78, транзит 33,04. Акорда: тарифный грузооборот 289 млрд т-км, +10%; объём +5,5%.
A12: Зерно | B12: Пресс-служба КТЖ, январь 2026: 14,3 млн т (+31%), экспорт 11 млн т (+33%). Узбекистан свыше 2 млн т (+41%), Центральная Азия 2,8 млн т (+27%).
A13: Уголь | B13: КТЖ, 11 месяцев 2025: 95,7 млн т (+3,3%), экспорт угля 31,2 млн т (+8%).
A14: Руда, 2026 | B14: КТЖ, январь–июль 2026 (пересказ RZD-Partner): железная руда 13,8 млн т (+16,6%), цветная руда 12,5 млн т, нефтепродукты 15,2 млн т, стройматериалы 11,3 млн т.
... A27: Чего в модели нет | B27: Интервью с грузовладельцами, коммерческие предложения казахстанских операторов, паспорт конкретного вагона, договор примыкания и фактический порожний тариф маршрута. Пока их нет, казахстанская ставка может отличаться от российского бенчмарка 1520.

Sheet Как пользоваться
A1: Модель парка вагонов — Казахстан, октябрь 2026
A3: 1. Меняйте только жёлтые ячейки на листе «Вводы».
A4: 2. Листы «Юнит», «Портфель», «Барьер», «Масштаб» и «Финансирование» пересчитают выручку, расходы, EBITDA, чистую прибыль, денежный поток, ROI, IRR, NPV и окупаемость.
A5: 3. Ставка крытого вагона — допущение. Подставьте ставку из коммерческого предложения, как только она появится.
A6: 4. Модель считает доход владельца вагона, а не маржу трейдера на зерне, угле или руде.
A7: 5. Тариф инфраструктуры и порожний рейс в базе платит клиент. Иная договорная схема ухудшает результат.
A8: 6. Это расчёт для решения, а не оценка имущества и не оферта.
A10: Презентация с выводами лежит рядом: Wagon-Park-Kazakhstan.pdf
